Workbook

Sheet Monthly Activity Log
A1: BA Team – Monthly Activity Log
A2: 📋 Fill in one row per activity. All yellow-highlighted columns are mandatory. Select values from the dropdown lists where provided.
A3: # | B3: Month | C3: Team Member | D3: Department / Module | E3: Ticket / Ref No. | F3: Project / Activity Name | G3: Description of Work | H3: Client | I3: Category | J3: Priority | K3: Status | L3: Notes / Blockers
A4: 1 | B4: April | C4: Shennaz | D4: SAP SD | F4: Aviation Surcharge (ZAVS) | G4: Configured and tested ZAVS pricing condition in QAS. Investigated condition determination and access sequence behaviour. Prepared emergency change documentation and UAT support. | H4: PetroSA | I4: Project | J4: High | K4: Completed
A5: 2 | B5: April | C5: Shennaz | D5: SAP MM | F5: Contract Expiry Control | G5: Investigated contract expiry controls for PO/SES processing. Performed QAS testing and documented findings for ABAP team. | H5: PetroSA | I5: Incident/Bug Fix | J5: Low | K5: Completed
A6: 3 | B6: April | C6: Shennaz | D6: SAP FI | F6: Ghana Company Code Project | G6: Reviewed chart of accounts mapping, account groups, number ranges and company code configuration requirements. | H6: PetroSA Ghana | I6: Project | J6: Medium | K6: In Progress
A7: 4 | B7: April | C7: Shennaz | D7: SAP FI/TRM | F7: Treasury Corrections | G7: Assisted with TBB1/TPM10 treasury postings and correction process analysis. | H7: PetroSA | I7: User Support | J7: Low | K7: Completed
A8: 5 | B8: April | C8: Shennaz | D8: SAP SD | F8: Credit Exposure Investigation | G8: Analysed customer credit exposure update issue and RVKRED77 behaviour. | H8: PetroSA | I8: Incident/Bug Fix | J8: Low | K8: Completed
A9: 6 | B9: April | C9: Shennaz | D9: SAP Travel | F9: Travel Management Support | G9: Resolved trip and expense claim issues and provided user support. | H9: SANPC | I9: Incident/Bug Fix | J9: Low | K9: Completed
A10: 7 | B10: April | C10: Shennaz | D10: SAP FI | F10: Period-End Support | G10: Supported period-end activities including balance carry-forward and account investigations. | H10: PetroSA | I10: Incident/Bug Fix | J10: Low | K10: Completed
A11: 8 | B11: April | C11: Shennaz | D11: SAP MM | F11: PO Output Notifications | G11: Assisted in Investigated workflow and email notification issues for purchase orders. | H11: PetroSA | I11: Incident/Bug Fix | J11: Low | K11: Completed
A12: 9 | B12: April | C12: Nyameka | D12: HR/Payroll | E12: 69585655 | F12: Payslips- October 2025 | G12: Incorrect for SFF due to SARS Bi-Annual. SARS Payment is not aligned to Sage for SANPC. | H12: SANPC | I12: Admin/Config | J12: Low | K12: In Progress
A13: 10 | B13: April | C13: Nyameka | D13: HR/Payroll | E13: 69585765 | F13: July Backpay line vs Backpay Overtime line | G13: July Backpay Line to be aligned and removed from Overtime in August 2025 payroll. | H13: SANPC | I13: Admin/Config | J13: Low | K13: In Progress
A14: 11 | B14: April | C14: Nyameka | D14: HR/Payroll | E14: 69585703 | F14: EMP 201 Payments Sep to Nov | G14: Payment does not reconcile due to item on Line 5. | H14: SANPC | I14: Admin/Config | J14: Low | K14: In Progress
A15: 12 | B15: April | C15: Nyameka | D15: HR/Payroll | E15: 69585655 | F15: October 2025 Payslip Discrepancy | G15: The SARS payment reflected in the October 2025 payslips is not aligned with Sage records for SANPC. | H15: SANPC | I15: Admin/Config | J15: Low | K15: In Progress
A16: 13 | B16: April | C16: Nyameka | D16: HR/Payroll | E16: 71880714 | F16: Run Time error | G16: Run time error investigation. | H16: SANPC | I16: Incident/Bug Fix | J16: Low | K16: In Progress
A17: 14 | B17: April | C17: Nyameka | D17: SAP HR | F17: PetroSA Solidarity Premium Update | G17: PetroSA Solidarity Premium Update. | H17: PetroSA | I17: Admin/Config | J17: Low | K17: Completed
A18: 15 | B18: April | C18: Nyameka | D18: SAP HR | F18: PetroSA Mortgage Premium Update | G18: PetroSA Mortgage Premium Update. | H18: PetroSA | I18: Admin/Config | J18: Low | K18: Completed
A19: 16 | B19: April | C19: Nyameka | D19: SAP HR | F19: PetroSA COID Premium Update | G19: PetroSA COID Premium Update. | H19: PetroSA | I19: Admin/Config | J19: Low | K19: Completed
A20: 17 | B20: April | C20: Lindiwe | D20: IT | E20: 77317642 | F20: Signing Hub | G20: Signing hub access. | H20: SANPC | I20: Incident/Bug Fix | J20: Low | K20: Completed
A21: 18 | B21: April | C21: Lindiwe | D21: IT | E21: 76861404 | F21: BPM - Password Resets | G21: Resetting all BPM/ACCPAC passwords for the users that are using the system. | H21: SANPC | I21: User Support | J21: Low | K21: Completed
A22: 19 | B22: April | C22: Lindiwe | D22: IT | E22: Emails | F22: BPM - Business Connect Loading | G22: Loading Business connect, MPLS, Network points, Sage Support PO GRV. | H22: SANPC | I22: User Support | J22: Low | K22: Completed
A23: 20 | B23: April | C23: Lindiwe | D23: Finance | E23: Emails | F23: BPM - RCP Investigation | G23: Check where the RCPs are stuck. | H23: SANPC/SFF | I23: Incident/Bug Fix | J23: Low | K23: Completed
A24: 21 | B24: April | C24: Lindiwe | D24: IT | E24: Emails | F24: BPM - Req Allocation | G24: Allocating the Reqs to correct approvers. | H24: SANPC | I24: User Support | J24: Low | K24: Completed
A25: 22 | B25: April | C25: Lindiwe | D25: IT | E25: Emails | F25: BPM - Transaction Re-allocation | G25: Re-allocate transactions to Sechaba for approval. | H25: SANPC | I25: User Support | J25: Low | K25: Completed
A26: 23 | B26: April | C26: Lindiwe | D26: IT | E26: Emails | F26: BPM - Scope of Work Loading | G26: Loading Scope of work for UPS, VMware licenses and Dell laptop Charges. | H26: SANPC | I26: User Support | J26: Low | K26: Completed
A27: 24 | B27: April | C27: Lindiwe | D27: IT | E27: 77314897 | F27: QBCON Installation | G27: Installation of QBCON-Plant Maintenance Icon on laptop. | H27: SANPC | I27: User Support | J27: Low | K27: Completed
A28: 25 | B28: April | C28: Lindiwe | D28: IT | E28: Emails | F28: BPM - Discard Reqs/POs | G28: Discarding all the Reqs Or POs as per the user's Request. | H28: SANPC | I28: User Support | J28: Low | K28: Completed
A29: 26 | B29: April | C29: Lindiwe | D29: IT | E29: Emails | F29: BPM - Grant Access | G29: Granting Access to BPM for Wayne, Comfort Bunting and Azarias. | H29: SANPC | I29: Incident/Bug Fix | J29: Low | K29: Completed
A30: 27 | B30: April | C30: Lindiwe | D30: IT | E30: Emails | F30: Signing Hub - Grant Access | G30: Granting Access to Signing hub for Wayne, Comfort Bunting and Azarias. | H30: SANPC | I30: Incident/Bug Fix | J30: Low | K30: Completed
A31: 28 | B31: May | C31: T A Willems | D31: IT | F31: ISS Upgrade - QAS Server Testing | G31: Encountered issues relating to TempDB and server connectivity. Resolved with assistance from Infrastructure Team. | H31: PetroSA | I31: Project | J31: Medium | K31: Completed
A32: 29 | B32: May | C32: T A Willems | D32: IT | E32: Problem:145411 | F32: IIS Tampering - EDI Application Recovery | G32: Investigated IIS Tampering which resulted in EDI Business Application being unavailable for more than 24 hours. Resolved and provided input to Incident Report. | H32: PetroSA | I32: Incident/Bug Fix | J32: High | K32: Completed
A33: 30 | B33: May | C33: T A Willems | D33: SAP HR | E33: CRQ: 77012428 | F33: Compensation Statement - Alternate Solution | G33: Developed, tested with End Users and released. Deployed via emergency Change to allow SAP Team more time to investigate long term solution. | H33: PetroSA | I33: Project | J33: High | K33: Completed
A34: 31 | B34: May | C34: T A Willems | D34: IT | F34: BBEE ESD Stakeholder Database Solution | G34: Initial session conducted with Business Users to understand requirements. Further deliberation required to determine direction. | H34: PetroSA/SANPC | I34: User Support | J34: Low | K34: Pending
A35: 32 | B35: May | C35: T A Willems | D35: IT | E35: 52710601 | F35: Procurement Email Tender Mailbox Replacement | G35: Requirement complete, planning complete, currently in development. Ongoing feedback sessions with Business Users. Planned finalisation Mid-June. | H35: PetroSA/SANPC | I35: Project | J35: Medium | K35: In Progress
A36: 33 | B36: May | C36: T A Willems | D36: IT | F36: ISS Upgrade - Procurement Public Website Update | G36: Development complete, awaiting time from Project Team to confirm SQL Databases/Tables/Views before finalising and sending to CCB for Go Live. | H36: PetroSA | I36: Project | J36: Medium | K36: In Progress
A37: 34 | B37: May | C37: T A Willems | D37: IT | F37: ISS Production - SQL 2022 Cluster Build | G37: Specifications agreed with Infrastructure, Project Team and Vendor. SQL Server 2022 Cluster build started. To be finalised next week. | H37: PetroSA | I37: Project | J37: Medium | K37: In Progress
A38: 35 | B38: May | C38: T A Willems | D38: IT | F38: AG Audit Ad-Hoc Support | G38: Ongoing ad-hoc requests for AG Audit queries for Security and Business Applications Team. | H38: PetroSA | I38: User Support | J38: Low | K38: In Progress
A39: 36 | B39: May | C39: T A Willems | D39: IT | F39: Customer Online Application Relaunch | G39: Requirements sent to Business Users. Redesigned two business applications based on End User feedback. Currently in development. Next session 3 June. | H39: PetroSA | I39: Project | J39: Medium | K39: In Progress
A40: 37 | B40: May | C40: T A Willems | D40: IT | E40: Problem: 133172 | F40: ESS Problem Investigation | G40: Issues point to Meraki implemented during SD-WAN. Next step: get assistance from Infrastructure Team and MTN. Issue isolated to remote site access Web Applications in Parow. | H40: PetroSA | I40: Project | J40: Low | K40: In Progress
...

Sheet Summary Dashboard
A1: BA Team – Monthly Summary Dashboard
A2: 📊 All figures update automatically when the Monthly Activity Log is populated. Use the Month filter in B4 to view a specific month.
A4: Filter: Month | B4: All
A6: Total Activities | C6: Completed | E6: In Progress | G6: Pending | I6: % Completed | K6: Active Members
A7: =IF($B$4="All",COUNTIF('Monthly Activity Log'!C$4:C$200,"<>"),COUNTIFS('Monthly Activity Log'!B$4:B$200,$B$4,'Monthly Activity Log'!C$4:C$200,"<>")) | C7: =IF($B$4="All",COUNTIF('Monthly Activity Log'!K$4:K$200,"Completed"),COUNTIFS('Monthly Activity Log'!B$4:B$200,$B$4,'Monthly Activity Log'!K$4:K$200,"Completed")) | E7: =IF($B$4="All",COUNTIF('Monthly Activity Log'!K$4:K$200,"In Progress"),COUNTIFS('Monthly Activity Log'!B$4:B$200,$B$4,'Monthly Activity Log'!K$4:K$200,"In Progress")) | G7: =IF($B$4="All",COUNTIF('Monthly Activity Log'!K$4:K$200,"Pending"),COUNTIFS('Monthly Activity Log'!B$4:B$200,$B$4,'Monthly Activity Log'!K$4:K$200,"Pending")) | I7: =IFERROR(C7/A7,0) | K7: =IF(IF($B$4="All",COUNTIF('Monthly Activity Log'!C$4:C$200,"Shennaz"),COUNTIFS('Monthly Activity Log'!B$4:B$200,$B$4,'Monthly Activity Log'!C$4:C$200,"Shennaz"))>0,1,0)+IF(IF($B$4="All",COUNTIF('Monthly Activity Log'!C$4:C$200,"Nyameka"),COUNTIFS('Monthly Activity Log'!B$4:B$200,$B$4,'Monthly Activity Log'!C$4:C$200,"Nyameka"))>0,1,0)+IF(IF($B$4="All",COUNTIF('Monthly Activity Log'!C$4:C$200,"Lindiwe"),COUNTIFS('Monthly Activity Log'!B$4:B$200,$B$4,'Monthly Activity Log'!C$4:C$200,"Lindiwe"))>0,1,0)+IF(IF($B$4="All",COUNTIF('Monthly Activity Log'!C$4:C$200,"T A Willems"),COUNTIFS('Monthly Activity Log'!B$4:B$200,$B$4,'Monthly Activity Log'!C$4:C$200,"T A Willems"))>0,1,0)+IF(IF($B$4="All",COUNTIF('Monthly Activity Log'!C$4:C$200,"Mphatheleni Matidze"),COUNTIFS('Monthly Activity Log'!B$4:B$200,$B$4,'Monthly Activity Log'!C$4:C$200,"Mphatheleni Matidze"))>0,1,0)
A10: ACTIVITIES PER TEAM MEMBER
A11: Team Member | B11: Total | C11: Completed | D11: In Progress | E11: Pending | F11: % Done
A12: Shennaz | B12: =IF($B$4="All",COUNTIF('Monthly Activity Log'!C$4:C$200,"Shennaz"),COUNTIFS('Monthly Activity Log'!B$4:B$200,$B$4,'Monthly Activity Log'!C$4:C$200,"Shennaz")) | C12: =IF($B$4="All",COUNTIFS('Monthly Activity Log'!C$4:C$200,"Shennaz",'Monthly Activity Log'!K$4:K$200,"Completed"),COUNTIFS('Monthly Activity Log'!B$4:B$200,$B$4,'Monthly Activity Log'!C$4:C$200,"Shennaz",'Monthly Activity Log'!K$4:K$200,"Completed")) | D12: =IF($B$4="All",COUNTIFS('Monthly Activity Log'!C$4:C$200,"Shennaz",'Monthly Activity Log'!K$4:K$200,"In Progress"),COUNTIFS('Monthly Activity Log'!B$4:B$200,$B$4,'Monthly Activity Log'!C$4:C$200,"Shennaz",'Monthly Activity Log'!K$4:K$200,"In Progress")) | E12: =IF($B$4="All",COUNTIFS('Monthly Activity Log'!C$4:C$200,"Shennaz",'Monthly Activity Log'!K$4:K$200,"Pending"),COUNTIFS('Monthly Activity Log'!B$4:B$200,$B$4,'Monthly Activity Log'!C$4:C$200,"Shennaz",'Monthly Activity Log'!K$4:K$200,"Pending")) | F12: =IFERROR(C12/B12,0)
A13: Nyameka | B13: =IF($B$4="All",COUNTIF('Monthly Activity Log'!C$4:C$200,"Nyameka"),COUNTIFS('Monthly Activity Log'!B$4:B$200,$B$4,'Monthly Activity Log'!C$4:C$200,"Nyameka")) | C13: =IF($B$4="All",COUNTIFS('Monthly Activity Log'!C$4:C$200,"Nyameka",'Monthly Activity Log'!K$4:K$200,"Completed"),COUNTIFS('Monthly Activity Log'!B$4:B$200,$B$4,'Monthly Activity Log'!C$4:C$200,"Nyameka",'Monthly Activity Log'!K$4:K$200,"Completed")) | D13: =IF($B$4="All",COUNTIFS('Monthly Activity Log'!C$4:C$200,"Nyameka",'Monthly Activity Log'!K$4:K$200,"In Progress"),COUNTIFS('Monthly Activity Log'!B$4:B$200,$B$4,'Monthly Activity Log'!C$4:C$200,"Nyameka",'Monthly Activity Log'!K$4:K$200,"In Progress")) | E13: =IF($B$4="All",COUNTIFS('Monthly Activity Log'!C$4:C$200,"Nyameka",'Monthly Activity Log'!K$4:K$200,"Pending"),COUNTIFS('Monthly Activity Log'!B$4:B$200,$B$4,'Monthly Activity Log'!C$4:C$200,"Nyameka",'Monthly Activity Log'!K$4:K$200,"Pending")) | F13: =IFERROR(C13/B13,0)
A14: Lindiwe | B14: =IF($B$4="All",COUNTIF('Monthly Activity Log'!C$4:C$200,"Lindiwe"),COUNTIFS('Monthly Activity Log'!B$4:B$200,$B$4,'Monthly Activity Log'!C$4:C$200,"Lindiwe")) | C14: =IF($B$4="All",COUNTIFS('Monthly Activity Log'!C$4:C$200,"Lindiwe",'Monthly Activity Log'!K$4:K$200,"Completed"),COUNTIFS('Monthly Activity Log'!B$4:B$200,$B$4,'Monthly Activity Log'!C$4:C$200,"Lindiwe",'Monthly Activity Log'!K$4:K$200,"Completed")) | D14: =IF($B$4="All",COUNTIFS('Monthly Activity Log'!C$4:C$200,"Lindiwe",'Monthly Activity Log'!K$4:K$200,"In Progress"),COUNTIFS('Monthly Activity Log'!B$4:B$200,$B$4,'Monthly Activity Log'!C$4:C$200,"Lindiwe",'Monthly Activity Log'!K$4:K$200,"In Progress")) | E14: =IF($B$4="All",COUNTIFS('Monthly Activity Log'!C$4:C$200,"Lindiwe",'Monthly Activity Log'!K$4:K$200,"Pending"),COUNTIFS('Monthly Activity Log'!B$4:B$200,$B$4,'Monthly Activity Log'!C$4:C$200,"Lindiwe",'Monthly Activity Log'!K$4:K$200,"Pending")) | F14: =IFERROR(C14/B14,0)
A15: T A Willems | B15: =IF($B$4="All",COUNTIF('Monthly Activity Log'!C$4:C$200,"T A Willems"),COUNTIFS('Monthly Activity Log'!B$4:B$200,$B$4,'Monthly Activity Log'!C$4:C$200,"T A Willems")) | C15: =IF($B$4="All",COUNTIFS('Monthly Activity Log'!C$4:C$200,"T A Willems",'Monthly Activity Log'!K$4:K$200,"Completed"),COUNTIFS('Monthly Activity Log'!B$4:B$200,$B$4,'Monthly Activity Log'!C$4:C$200,"T A Willems",'Monthly Activity Log'!K$4:K$200,"Completed")) | D15: =IF($B$4="All",COUNTIFS('Monthly Activity Log'!C$4:C$200,"T A Willems",'Monthly Activity Log'!K$4:K$200,"In Progress"),COUNTIFS('Monthly Activity Log'!B$4:B$200,$B$4,'Monthly Activity Log'!C$4:C$200,"T A Willems",'Monthly Activity Log'!K$4:K$200,"In Progress")) | E15: =IF($B$4="All",COUNTIFS('Monthly Activity Log'!C$4:C$200,"T A Willems",'Monthly Activity Log'!K$4:K$200,"Pending"),COUNTIFS('Monthly Activity Log'!B$4:B$200,$B$4,'Monthly Activity Log'!C$4:C$200,"T A Willems",'Monthly Activity Log'!K$4:K$200,"Pending")) | F15: =IFERROR(C15/B15,0)
A16: Mphatheleni Matidze | B16: =IF($B$4="All",COUNTIF('Monthly Activity Log'!C$4:C$200,"Mphatheleni Matidze"),COUNTIFS('Monthly Activity Log'!B$4:B$200,$B$4,'Monthly Activity Log'!C$4:C$200,"Mphatheleni Matidze")) | C16: =IF($B$4="All",COUNTIFS('Monthly Activity Log'!C$4:C$200,"Mphatheleni Matidze",'Monthly Activity Log'!K$4:K$200,"Completed"),COUNTIFS('Monthly Activity Log'!B$4:B$200,$B$4,'Monthly Activity Log'!C$4:C$200,"Mphatheleni Matidze",'Monthly Activity Log'!K$4:K$200,"Completed")) | D16: =IF($B$4="All",COUNTIFS('Monthly Activity Log'!C$4:C$200,"Mphatheleni Matidze",'Monthly Activity Log'!K$4:K$200,"In Progress"),COUNTIFS('Monthly Activity Log'!B$4:B$200,$B$4,'Monthly Activity Log'!C$4:C$200,"Mphatheleni Matidze",'Monthly Activity Log'!K$4:K$200,"In Progress")) | E16: =IF($B$4="All",COUNTIFS('Monthly Activity Log'!C$4:C$200,"Mphatheleni Matidze",'Monthly Activity Log'!K$4:K$200,"Pending"),COUNTIFS('Monthly Activity Log'!B$4:B$200,$B$4,'Monthly Activity Log'!C$4:C$200,"Mphatheleni Matidze",'Monthly Activity Log'!K$4:K$200,"Pending")) | F16: =IFERROR(C16/B16,0)
A17: TOTAL | B17: =SUM(B12:B16) | C17: =SUM(C12:C16) | D17: =SUM(D12:D16) | E17: =SUM(E12:E16) | F17: =IFERROR(C17/B17,0)
A19: ACTIVITIES BY CATEGORY | H19: ACTIVITIES BY CLIENT
A20: Category | B20: Count | C20: % of Total | H20: Client | I20: Count | J20: % of Total
A21: Project | B21: =IF($B$4="All",COUNTIF('Monthly Activity Log'!I$4:I$200,"Project"),COUNTIFS('Monthly Activity Log'!B$4:B$200,$B$4,'Monthly Activity Log'!I$4:I$200,"Project")) | C21: =IFERROR(B21/A7,0) | H21: SANPC | I21: =IF($B$4="All",COUNTIF('Monthly Activity Log'!H$4:H$200,"SANPC"),COUNTIFS('Monthly Activity Log'!B$4:B$200,$B$4,'Monthly Activity Log'!H$4:H$200,"SANPC")) | J21: =IFERROR(I21/A7,0)
A22: Incident/Bug Fix | B22: =IF($B$4="All",COUNTIF('Monthly Activity Log'!I$4:I$200,"Incident/Bug Fix"),COUNTIFS('Monthly Activity Log'!B$4:B$200,$B$4,'Monthly Activity Log'!I$4:I$200,"Incident/Bug Fix")) | C22: =IFERROR(B22/A7,0) | H22: PetroSA | I22: =IF($B$4="All",COUNTIF('Monthly Activity Log'!H$4:H$200,"PetroSA"),COUNTIFS('Monthly Activity Log'!B$4:B$200,$B$4,'Monthly Activity Log'!H$4:H$200,"PetroSA")) | J22: =IFERROR(I22/A7,0)
A23: Change Request | B23: =IF($B$4="All",COUNTIF('Monthly Activity Log'!I$4:I$200,"Change Request"),COUNTIFS('Monthly Activity Log'!B$4:B$200,$B$4,'Monthly Activity Log'!I$4:I$200,"Change Request")) | C23: =IFERROR(B23/A7,0) | H23: PetroSA Ghana | I23: =IF($B$4="All",COUNTIF('Monthly Activity Log'!H$4:H$200,"PetroSA Ghana"),COUNTIFS('Monthly Activity Log'!B$4:B$200,$B$4,'Monthly Activity Log'!H$4:H$200,"PetroSA Ghana")) | J23: =IFERROR(I23/A7,0)
A24: User Support | B24: =IF($B$4="All",COUNTIF('Monthly Activity Log'!I$4:I$200,"User Support"),COUNTIFS('Monthly Activity Log'!B$4:B$200,$B$4,'Monthly Activity Log'!I$4:I$200,"User Support")) | C24: =IFERROR(B24/A7,0) | H24: Legacy/CEF | I24: =IF($B$4="All",COUNTIF('Monthly Activity Log'!H$4:H$200,"Legacy/CEF"),COUNTIFS('Monthly Activity Log'!B$4:B$200,$B$4,'Monthly Activity Log'!H$4:H$200,"Legacy/CEF")) | J24: =IFERROR(I24/A7,0)
A25: Admin/Config | B25: =IF($B$4="All",COUNTIF('Monthly Activity Log'!I$4:I$200,"Admin/Config"),COUNTIFS('Monthly Activity Log'!B$4:B$200,$B$4,'Monthly Activity Log'!I$4:I$200,"Admin/Config")) | C25: =IFERROR(B25/A7,0) | H25: SANPC/SFF | I25: =IF($B$4="All",COUNTIF('Monthly Activity Log'!H$4:H$200,"SANPC/SFF"),COUNTIFS('Monthly Activity Log'!B$4:B$200,$B$4,'Monthly Activity Log'!H$4:H$200,"SANPC/SFF")) | J25: =IFERROR(I25/A7,0)
A26: Reporting | B26: =IF($B$4="All",COUNTIF('Monthly Activity Log'!I$4:I$200,"Reporting"),COUNTIFS('Monthly Activity Log'!B$4:B$200,$B$4,'Monthly Activity Log'!I$4:I$200,"Reporting")) | C26: =IFERROR(B26/A7,0) | H26: PetroSA/SANPC | I26: =IF($B$4="All",COUNTIF('Monthly Activity Log'!H$4:H$200,"PetroSA/SANPC"),COUNTIFS('Monthly Activity Log'!B$4:B$200,$B$4,'Monthly Activity Log'!H$4:H$200,"PetroSA/SANPC")) | J26: =IFERROR(I26/A7,0)
A27: Mentoring | B27: =IF($B$4="All",COUNTIF('Monthly Activity Log'!I$4:I$200,"Mentoring"),COUNTIFS('Monthly Activity Log'!B$4:B$200,$B$4,'Monthly Activity Log'!I$4:I$200,"Mentoring")) | C27: =IFERROR(B27/A7,0) | H27: Other | I27: =IF($B$4="All",COUNTIF('Monthly Activity Log'!H$4:H$200,"Other"),COUNTIFS('Monthly Activity Log'!B$4:B$200,$B$4,'Monthly Activity Log'!H$4:H$200,"Other")) | J27: =IFERROR(I27/A7,0)
A28: Other | B28: =IF($B$4="All",COUNTIF('Monthly Activity Log'!I$4:I$200,"Other"),COUNTIFS('Monthly Activity Log'!B$4:B$200,$B$4,'Monthly Activity Log'!I$4:I$200,"Other")) | C28: =IFERROR(B28/A7,0)

Sheet Team Member View
A1: BA Team – Team Member Workload View
A2: 👤 Select a team member in B3 to filter. Select 'All' to see the full team. Updates automatically from the Monthly Activity Log.
A3: Team Member: | B3: All | D3: Month: | E3: All
A4: # | B4: Month | C4: Team Member | D4: Dept/Module | E4: Ticket No. | F4: Activity Name | G4: Description | H4: Client | I4: Category | J4: Priority | K4: Status
A5: =IF(AND(('Monthly Activity Log'!C4<>""),(OR($B$3="All",'Monthly Activity Log'!C4=$B$3)),(OR($E$3="All",'Monthly Activity Log'!B4=$E$3))),ROW()-4,"") | B5: =IF(AND(('Monthly Activity Log'!C4<>""),(OR($B$3="All",'Monthly Activity Log'!C4=$B$3)),(OR($E$3="All",'Monthly Activity Log'!B4=$E$3))),'Monthly Activity Log'!B4,"") | C5: =IF(AND(('Monthly Activity Log'!C4<>""),(OR($B$3="All",'Monthly Activity Log'!C4=$B$3)),(OR($E$3="All",'Monthly Activity Log'!B4=$E$3))),'Monthly Activity Log'!C4,"") | D5: =IF(AND(('Monthly Activity Log'!C4<>""),(OR($B$3="All",'Monthly Activity Log'!C4=$B$3)),(OR($E$3="All",'Monthly Activity Log'!B4=$E$3))),'Monthly Activity Log'!D4,"") | E5: =IF(AND(('Monthly Activity Log'!C4<>""),(OR($B$3="All",'Monthly Activity Log'!C4=$B$3)),(OR($E$3="All",'Monthly Activity Log'!B4=$E$3))),'Monthly Activity Log'!E4,"") | F5: =IF(AND(('Monthly Activity Log'!C4<>""),(OR($B$3="All",'Monthly Activity Log'!C4=$B$3)),(OR($E$3="All",'Monthly Activity Log'!B4=$E$3))),'Monthly Activity Log'!F4,"") | G5: =IF(AND(('Monthly Activity Log'!C4<>""),(OR($B$3="All",'Monthly Activity Log'!C4=$B$3)),(OR($E$3="All",'Monthly Activity Log'!B4=$E$3))),'Monthly Activity Log'!G4,"") | H5: =IF(AND(('Monthly Activity Log'!C4<>""),(OR($B$3="All",'Monthly Activity Log'!C4=$B$3)),(OR($E$3="All",'Monthly Activity Log'!B4=$E$3))),'Monthly Activity Log'!H4,"") | I5: =IF(AND(('Monthly Activity Log'!C4<>""),(OR($B$3="All",'Monthly Activity Log'!C4=$B$3)),(OR($E$3="All",'Monthly Activity Log'!B4=$E$3))),'Monthly Activity Log'!I4,"") | J5: =IF(AND(('Monthly Activity Log'!C4<>""),(OR($B$3="All",'Monthly Activity Log'!C4=$B$3)),(OR($E$3="All",'Monthly Activity Log'!B4=$E$3))),'Monthly Activity Log'!J4,"") | K5: =IF(AND(('Monthly Activity Log'!C4<>""),(OR($B$3="All",'Monthly Activity Log'!C4=$B$3)),(OR($E$3="All",'Monthly Activity Log'!B4=$E$3))),'Monthly Activity Log'!K4,"")
A6: =IF(AND(('Monthly Activity Log'!C5<>""),(OR($B$3="All",'Monthly Activity Log'!C5=$B$3)),(OR($E$3="All",'Monthly Activity Log'!B5=$E$3))),ROW()-4,"") | B6: =IF(AND(('Monthly Activity Log'!C5<>""),(OR($B$3="All",'Monthly Activity Log'!C5=$B$3)),(OR($E$3="All",'Monthly Activity Log'!B5=$E$3))),'Monthly Activity Log'!B5,"") | C6: =IF(AND(('Monthly Activity Log'!C5<>""),(OR($B$3="All",'Monthly Activity Log'!C5=$B$3)),(OR($E$3="All",'Monthly Activity Log'!B5=$E$3))),'Monthly Activity Log'!C5,"") | D6: =IF(AND(('Monthly Activity Log'!C5<>""),(OR($B$3="All",'Monthly Activity Log'!C5=$B$3)),(OR($E$3="All",'Monthly Activity Log'!B5=$E$3))),'Monthly Activity Log'!D5,"") | E6: =IF(AND(('Monthly Activity Log'!C5<>""),(OR($B$3="All",'Monthly Activity Log'!C5=$B$3)),(OR($E$3="All",'Monthly Activity Log'!B5=$E$3))),'Monthly Activity Log'!E5,"") | F6: =IF(AND(('Monthly Activity Log'!C5<>""),(OR($B$3="All",'Monthly Activity Log'!C5=$B$3)),(OR($E$3="All",'Monthly Activity Log'!B5=$E$3))),'Monthly Activity Log'!F5,"") | G6: =IF(AND(('Monthly Activity Log'!C5<>""),(OR($B$3="All",'Monthly Activity Log'!C5=$B$3)),(OR($E$3="All",'Monthly Activity Log'!B5=$E$3))),'Monthly Activity Log'!G5,"") | H6: =IF(AND(('Monthly Activity Log'!C5<>""),(OR($B$3="All",'Monthly Activity Log'!C5=$B$3)),(OR($E$3="All",'Monthly Activity Log'!B5=$E$3))),'Monthly Activity Log'!H5,"") | I6: =IF(AND(('Monthly Activity Log'!C5<>""),(OR($B$3="All",'Monthly Activity Log'!C5=$B$3)),(OR($E$3="All",'Monthly Activity Log'!B5=$E$3))),'Monthly Activity Log'!I5,"") | J6: =IF(AND(('Monthly Activity Log'!C5<>""),(OR($B$3="All",'Monthly Activity Log'!C5=$B$3)),(OR($E$3="All",'Monthly Activity Log'!B5=$E$3))),'Monthly Activity Log'!J5,"") | K6: =IF(AND(('Monthly Activity Log'!C5<>""),(OR($B$3="All",'Monthly Activity Log'!C5=$B$3)),(OR($E$3="All",'Monthly Activity Log'!B5=$E$3))),'Monthly Activity Log'!K5,"")
A7: =IF(AND(('Monthly Activity Log'!C6<>""),(OR($B$3="All",'Monthly Activity Log'!C6=$B$3)),(OR($E$3="All",'Monthly Activity Log'!B6=$E$3))),ROW()-4,"") | B7: =IF(AND(('Monthly Activity Log'!C6<>""),(OR($B$3="All",'Monthly Activity Log'!C6=$B$3)),(OR($E$3="All",'Monthly Activity Log'!B6=$E$3))),'Monthly Activity Log'!B6,"") | C7: =IF(AND(('Monthly Activity Log'!C6<>""),(OR($B$3="All",'Monthly Activity Log'!C6=$B$3)),(OR($E$3="All",'Monthly Activity Log'!B6=$E$3))),'Monthly Activity Log'!C6,"") | D7: =IF(AND(('Monthly Activity Log'!C6<>""),(OR($B$3="All",'Monthly Activity Log'!C6=$B$3)),(OR($E$3="All",'Monthly Activity Log'!B6=$E$3))),'Monthly Activity Log'!D6,"") | E7: =IF(AND(('Monthly Activity Log'!C6<>""),(OR($B$3="All",'Monthly Activity Log'!C6=$B$3)),(OR($E$3="All",'Monthly Activity Log'!B6=$E$3))),'Monthly Activity Log'!E6,"") | F7: =IF(AND(('Monthly Activity Log'!C6<>""),(OR($B$3="All",'Monthly Activity Log'!C6=$B$3)),(OR($E$3="All",'Monthly Activity Log'!B6=$E$3))),'Monthly Activity Log'!F6,"") | G7: =IF(AND(('Monthly Activity Log'!C6<>""),(OR($B$3="All",'Monthly Activity Log'!C6=$B$3)),(OR($E$3="All",'Monthly Activity Log'!B6=$E$3))),'Monthly Activity Log'!G6,"") | H7: =IF(AND(('Monthly Activity Log'!C6<>""),(OR($B$3="All",'Monthly Activity Log'!C6=$B$3)),(OR($E$3="All",'Monthly Activity Log'!B6=$E$3))),'Monthly Activity Log'!H6,"") | I7: =IF(AND(('Monthly Activity Log'!C6<>""),(OR($B$3="All",'Monthly Activity Log'!C6=$B$3)),(OR($E$3="All",'Monthly Activity Log'!B6=$E$3))),'Monthly Activity Log'!I6,"") | J7: =IF(AND(('Monthly Activity Log'!C6<>""),(OR($B$3="All",'Monthly Activity Log'!C6=$B$3)),(OR($E$3="All",'Monthly Activity Log'!B6=$E$3))),'Monthly Activity Log'!J6,"") | K7: =IF(AND(('Monthly Activity Log'!C6<>""),(OR($B$3="All",'Monthly Activity Log'!C6=$B$3)),(OR($E$3="All",'Monthly Activity Log'!B6=$E$3))),'Monthly Activity Log'!K6,"")
A8: =IF(AND(('Monthly Activity Log'!C7<>""),(OR($B$3="All",'Monthly Activity Log'!C7=$B$3)),(OR($E$3="All",'Monthly Activity Log'!B7=$E$3))),ROW()-4,"") | B8: =IF(AND(('Monthly Activity Log'!C7<>""),(OR($B$3="All",'Monthly Activity Log'!C7=$B$3)),(OR($E$3="All",'Monthly Activity Log'!B7=$E$3))),'Monthly Activity Log'!B7,"") | C8: =IF(AND(('Monthly Activity Log'!C7<>""),(OR($B$3="All",'Monthly Activity Log'!C7=$B$3)),(OR($E$3="All",'Monthly Activity Log'!B7=$E$3))),'Monthly Activity Log'!C7,"") | D8: =IF(AND(('Monthly Activity Log'!C7<>""),(OR($B$3="All",'Monthly Activity Log'!C7=$B$3)),(OR($E$3="All",'Monthly Activity Log'!B7=$E$3))),'Monthly Activity Log'!D7,"") | E8: =IF(AND(('Monthly Activity Log'!C7<>""),(OR($B$3="All",'Monthly Activity Log'!C7=$B$3)),(OR($E$3="All",'Monthly Activity Log'!B7=$E$3))),'Monthly Activity Log'!E7,"") | F8: =IF(AND(('Monthly Activity Log'!C7<>""),(OR($B$3="All",'Monthly Activity Log'!C7=$B$3)),(OR($E$3="All",'Monthly Activity Log'!B7=$E$3))),'Monthly Activity Log'!F7,"") | G8: =IF(AND(('Monthly Activity Log'!C7<>""),(OR($B$3="All",'Monthly Activity Log'!C7=$B$3)),(OR($E$3="All",'Monthly Activity Log'!B7=$E$3))),'Monthly Activity Log'!G7,"") | H8: =IF(AND(('Monthly Activity Log'!C7<>""),(OR($B$3="All",'Monthly Activity Log'!C7=$B$3)),(OR($E$3="All",'Monthly Activity Log'!B7=$E$3))),'Monthly Activity Log'!H7,"") | I8: =IF(AND(('Monthly Activity Log'!C7<>""),(OR($B$3="All",'Monthly Activity Log'!C7=$B$3)),(OR($E$3="All",'Monthly Activity Log'!B7=$E$3))),'Monthly Activity Log'!I7,"") | J8: =IF(AND(('Monthly Activity Log'!C7<>""),(OR($B$3="All",'Monthly Activity Log'!C7=$B$3)),(OR($E$3="All",'Monthly Activity Log'!B7=$E$3))),'Monthly Activity Log'!J7,"") | K8: =IF(AND(('Monthly Activity Log'!C7<>""),(OR($B$3="All",'Monthly Activity Log'!C7=$B$3)),(OR($E$3="All",'Monthly Activity Log'!B7=$E$3))),'Monthly Activity Log'!K7,"")
A9: =IF(AND(('Monthly Activity Log'!C8<>""),(OR($B$3="All",'Monthly Activity Log'!C8=$B$3)),(OR($E$3="All",'Monthly Activity Log'!B8=$E$3))),ROW()-4,"") | B9: =IF(AND(('Monthly Activity Log'!C8<>""),(OR($B$3="All",'Monthly Activity Log'!C8=$B$3)),(OR($E$3="All",'Monthly Activity Log'!B8=$E$3))),'Monthly Activity Log'!B8,"") | C9: =IF(AND(('Monthly Activity Log'!C8<>""),(OR($B$3="All",'Monthly Activity Log'!C8=$B$3)),(OR($E$3="All",'Monthly Activity Log'!B8=$E$3))),'Monthly Activity Log'!C8,"") | D9: =IF(AND(('Monthly Activity Log'!C8<>""),(OR($B$3="All",'Monthly Activity Log'!C8=$B$3)),(OR($E$3="All",'Monthly Activity Log'!B8=$E$3))),'Monthly Activity Log'!D8,"") | E9: =IF(AND(('Monthly Activity Log'!C8<>""),(OR($B$3="All",'Monthly Activity Log'!C8=$B$3)),(OR($E$3="All",'Monthly Activity Log'!B8=$E$3))),'Monthly Activity Log'!E8,"") | F9: =IF(AND(('Monthly Activity Log'!C8<>""),(OR($B$3="All",'Monthly Activity Log'!C8=$B$3)),(OR($E$3="All",'Monthly Activity Log'!B8=$E$3))),'Monthly Activity Log'!F8,"") | G9: =IF(AND(('Monthly Activity Log'!C8<>""),(OR($B$3="All",'Monthly Activity Log'!C8=$B$3)),(OR($E$3="All",'Monthly Activity Log'!B8=$E$3))),'Monthly Activity Log'!G8,"") | H9: =IF(AND(('Monthly Activity Log'!C8<>""),(OR($B$3="All",'Monthly Activity Log'!C8=$B$3)),(OR($E$3="All",'Monthly Activity Log'!B8=$E$3))),'Monthly Activity Log'!H8,"") | I9: =IF(AND(('Monthly Activity Log'!C8<>""),(OR($B$3="All",'Monthly Activity Log'!C8=$B$3)),(OR($E$3="All",'Monthly Activity Log'!B8=$E$3))),'Monthly Activity Log'!I8,"") | J9: =IF(AND(('Monthly Activity Log'!C8<>""),(OR($B$3="All",'Monthly Activity Log'!C8=$B$3)),(OR($E$3="All",'Monthly Activity Log'!B8=$E$3))),'Monthly Activity Log'!J8,"") | K9: =IF(AND(('Monthly Activity Log'!C8<>""),(OR($B$3="All",'Monthly Activity Log'!C8=$B$3)),(OR($E$3="All",'Monthly Activity Log'!B8=$E$3))),'Monthly Activity Log'!K8,"")
A10: =IF(AND(('Monthly Activity Log'!C9<>""),(OR($B$3="All",'Monthly Activity Log'!C9=$B$3)),(OR($E$3="All",'Monthly Activity Log'!B9=$E$3))),ROW()-4,"") | B10: =IF(AND(('Monthly Activity Log'!C9<>""),(OR($B$3="All",'Monthly Activity Log'!C9=$B$3)),(OR($E$3="All",'Monthly Activity Log'!B9=$E$3))),'Monthly Activity Log'!B9,"") | C10: =IF(AND(('Monthly Activity Log'!C9<>""),(OR($B$3="All",'Monthly Activity Log'!C9=$B$3)),(OR($E$3="All",'Monthly Activity Log'!B9=$E$3))),'Monthly Activity Log'!C9,"") | D10: =IF(AND(('Monthly Activity Log'!C9<>""),(OR($B$3="All",'Monthly Activity Log'!C9=$B$3)),(OR($E$3="All",'Monthly Activity Log'!B9=$E$3))),'Monthly Activity Log'!D9,"") | E10: =IF(AND(('Monthly Activity Log'!C9<>""),(OR($B$3="All",'Monthly Activity Log'!C9=$B$3)),(OR($E$3="All",'Monthly Activity Log'!B9=$E$3))),'Monthly Activity Log'!E9,"") | F10: =IF(AND(('Monthly Activity Log'!C9<>""),(OR($B$3="All",'Monthly Activity Log'!C9=$B$3)),(OR($E$3="All",'Monthly Activity Log'!B9=$E$3))),'Monthly Activity Log'!F9,"") | G10: =IF(AND(('Monthly Activity Log'!C9<>""),(OR($B$3="All",'Monthly Activity Log'!C9=$B$3)),(OR($E$3="All",'Monthly Activity Log'!B9=$E$3))),'Monthly Activity Log'!G9,"") | H10: =IF(AND(('Monthly Activity Log'!C9<>""),(OR($B$3="All",'Monthly Activity Log'!C9=$B$3)),(OR($E$3="All",'Monthly Activity Log'!B9=$E$3))),'Monthly Activity Log'!H9,"") | I10: =IF(AND(('Monthly Activity Log'!C9<>""),(OR($B$3="All",'Monthly Activity Log'!C9=$B$3)),(OR($E$3="All",'Monthly Activity Log'!B9=$E$3))),'Monthly Activity Log'!I9,"") | J10: =IF(AND(('Monthly Activity Log'!C9<>""),(OR($B$3="All",'Monthly Activity Log'!C9=$B$3)),(OR($E$3="All",'Monthly Activity Log'!B9=$E$3))),'Monthly Activity Log'!J9,"") | K10: =IF(AND(('Monthly Activity Log'!C9<>""),(OR($B$3="All",'Monthly Activity Log'!C9=$B$3)),(OR($E$3="All",'Monthly Activity Log'!B9=$E$3))),'Monthly Activity Log'!K9,"")
A11: =IF(AND(('Monthly Activity Log'!C10<>""),(OR($B$3="All",'Monthly Activity Log'!C10=$B$3)),(OR($E$3="All",'Monthly Activity Log'!B10=$E$3))),ROW()-4,"") | B11: =IF(AND(('Monthly Activity Log'!C10<>""),(OR($B$3="All",'Monthly Activity Log'!C10=$B$3)),(OR($E$3="All",'Monthly Activity Log'!B10=$E$3))),'Monthly Activity Log'!B10,"") | C11: =IF(AND(('Monthly Activity Log'!C10<>""),(OR($B$3="All",'Monthly Activity Log'!C10=$B$3)),(OR($E$3="All",'Monthly Activity Log'!B10=$E$3))),'Monthly Activity Log'!C10,"") | D11: =IF(AND(('Monthly Activity Log'!C10<>""),(OR($B$3="All",'Monthly Activity Log'!C10=$B$3)),(OR($E$3="All",'Monthly Activity Log'!B10=$E$3))),'Monthly Activity Log'!D10,"") | E11: =IF(AND(('Monthly Activity Log'!C10<>""),(OR($B$3="All",'Monthly Activity Log'!C10=$B$3)),(OR($E$3="All",'Monthly Activity Log'!B10=$E$3))),'Monthly Activity Log'!E10,"") | F11: =IF(AND(('Monthly Activity Log'!C10<>""),(OR($B$3="All",'Monthly Activity Log'!C10=$B$3)),(OR($E$3="All",'Monthly Activity Log'!B10=$E$3))),'Monthly Activity Log'!F10,"") | G11: =IF(AND(('Monthly Activity Log'!C10<>""),(OR($B$3="All",'Monthly Activity Log'!C10=$B$3)),(OR($E$3="All",'Monthly Activity Log'!B10=$E$3))),'Monthly Activity Log'!G10,"") | H11: =IF(AND(('Monthly Activity Log'!C10<>""),(OR($B$3="All",'Monthly Activity Log'!C10=$B$3)),(OR($E$3="All",'Monthly Activity Log'!B10=$E$3))),'Monthly Activity Log'!H10,"") | I11: =IF(AND(('Monthly Activity Log'!C10<>""),(OR($B$3="All",'Monthly Activity Log'!C10=$B$3)),(OR($E$3="All",'Monthly Activity Log'!B10=$E$3))),'Monthly Activity Log'!I10,"") | J11: =IF(AND(('Monthly Activity Log'!C10<>""),(OR($B$3="All",'Monthly Activity Log'!C10=$B$3)),(OR($E$3="All",'Monthly Activity Log'!B10=$E$3))),'Monthly Activity Log'!J10,"") | K11: =IF(AND(('Monthly Activity Log'!C10<>""),(OR($B$3="All",'Monthly Activity Log'!C10=$B$3)),(OR($E$3="All",'Monthly Activity Log'!B10=$E$3))),'Monthly Activity Log'!K10,"")
A12: =IF(AND(('Monthly Activity Log'!C11<>""),(OR($B$3="All",'Monthly Activity Log'!C11=$B$3)),(OR($E$3="All",'Monthly Activity Log'!B11=$E$3))),ROW()-4,"") | B12: =IF(AND(('Monthly Activity Log'!C11<>""),(OR($B$3="All",'Monthly Activity Log'!C11=$B$3)),(OR($E$3="All",'Monthly Activity Log'!B11=$E$3))),'Monthly Activity Log'!B11,"") | C12: =IF(AND(('Monthly Activity Log'!C11<>""),(OR($B$3="All",'Monthly Activity Log'!C11=$B$3)),(OR($E$3="All",'Monthly Activity Log'!B11=$E$3))),'Monthly Activity Log'!C11,"") | D12: =IF(AND(('Monthly Activity Log'!C11<>""),(OR($B$3="All",'Monthly Activity Log'!C11=$B$3)),(OR($E$3="All",'Monthly Activity Log'!B11=$E$3))),'Monthly Activity Log'!D11,"") | E12: =IF(AND(('Monthly Activity Log'!C11<>""),(OR($B$3="All",'Monthly Activity Log'!C11=$B$3)),(OR($E$3="All",'Monthly Activity Log'!B11=$E$3))),'Monthly Activity Log'!E11,"") | F12: =IF(AND(('Monthly Activity Log'!C11<>""),(OR($B$3="All",'Monthly Activity Log'!C11=$B$3)),(OR($E$3="All",'Monthly Activity Log'!B11=$E$3))),'Monthly Activity Log'!F11,"") | G12: =IF(AND(('Monthly Activity Log'!C11<>""),(OR($B$3="All",'Monthly Activity Log'!C11=$B$3)),(OR($E$3="All",'Monthly Activity Log'!B11=$E$3))),'Monthly Activity Log'!G11,"") | H12: =IF(AND(('Monthly Activity Log'!C11<>""),(OR($B$3="All",'Monthly Activity Log'!C11=$B$3)),(OR($E$3="All",'Monthly Activity Log'!B11=$E$3))),'Monthly Activity Log'!H11,"") | I12: =IF(AND(('Monthly Activity Log'!C11<>""),(OR($B$3="All",'Monthly Activity Log'!C11=$B$3)),(OR($E$3="All",'Monthly Activity Log'!B11=$E$3))),'Monthly Activity Log'!I11,"") | J12: =IF(AND(('Monthly Activity Log'!C11<>""),(OR($B$3="All",'Monthly Activity Log'!C11=$B$3)),(OR($E$3="All",'Monthly Activity Log'!B11=$E$3))),'Monthly Activity Log'!J11,"") | K12: =IF(AND(('Monthly Activity Log'!C11<>""),(OR($B$3="All",'Monthly Activity Log'!C11=$B$3)),(OR($E$3="All",'Monthly Activity Log'!B11=$E$3))),'Monthly Activity Log'!K11,"")
A13: =IF(AND(('Monthly Activity Log'!C12<>""),(OR($B$3="All",'Monthly Activity Log'!C12=$B$3)),(OR($E$3="All",'Monthly Activity Log'!B12=$E$3))),ROW()-4,"") | B13: =IF(AND(('Monthly Activity Log'!C12<>""),(OR($B$3="All",'Monthly Activity Log'!C12=$B$3)),(OR($E$3="All",'Monthly Activity Log'!B12=$E$3))),'Monthly Activity Log'!B12,"") | C13: =IF(AND(('Monthly Activity Log'!C12<>""),(OR($B$3="All",'Monthly Activity Log'!C12=$B$3)),(OR($E$3="All",'Monthly Activity Log'!B12=$E$3))),'Monthly Activity Log'!C12,"") | D13: =IF(AND(('Monthly Activity Log'!C12<>""),(OR($B$3="All",'Monthly Activity Log'!C12=$B$3)),(OR($E$3="All",'Monthly Activity Log'!B12=$E$3))),'Monthly Activity Log'!D12,"") | E13: =IF(AND(('Monthly Activity Log'!C12<>""),(OR($B$3="All",'Monthly Activity Log'!C12=$B$3)),(OR($E$3="All",'Monthly Activity Log'!B12=$E$3))),'Monthly Activity Log'!E12,"") | F13: =IF(AND(('Monthly Activity Log'!C12<>""),(OR($B$3="All",'Monthly Activity Log'!C12=$B$3)),(OR($E$3="All",'Monthly Activity Log'!B12=$E$3))),'Monthly Activity Log'!F12,"") | G13: =IF(AND(('Monthly Activity Log'!C12<>""),(OR($B$3="All",'Monthly Activity Log'!C12=$B$3)),(OR($E$3="All",'Monthly Activity Log'!B12=$E$3))),'Monthly Activity Log'!G12,"") | H13: =IF(AND(('Monthly Activity Log'!C12<>""),(OR($B$3="All",'Monthly Activity Log'!C12=$B$3)),(OR($E$3="All",'Monthly Activity Log'!B12=$E$3))),'Monthly Activity Log'!H12,"") | I13: =IF(AND(('Monthly Activity Log'!C12<>""),(OR($B$3="All",'Monthly Activity Log'!C12=$B$3)),(OR($E$3="All",'Monthly Activity Log'!B12=$E$3))),'Monthly Activity Log'!I12,"") | J13: =IF(AND(('Monthly Activity Log'!C12<>""),(OR($B$3="All",'Monthly Activity Log'!C12=$B$3)),(OR($E$3="All",'Monthly Activity Log'!B12=$E$3))),'Monthly Activity Log'!J12,"") | K13: =IF(AND(('Monthly Activity Log'!C12<>""),(OR($B$3="All",'Monthly Activity Log'!C12=$B$3)),(OR($E$3="All",'Monthly Activity Log'!B12=$E$3))),'Monthly Activity Log'!K12,"")
A14: =IF(AND(('Monthly Activity Log'!C13<>""),(OR($B$3="All",'Monthly Activity Log'!C13=$B$3)),(OR($E$3="All",'Monthly Activity Log'!B13=$E$3))),ROW()-4,"") | B14: =IF(AND(('Monthly Activity Log'!C13<>""),(OR($B$3="All",'Monthly Activity Log'!C13=$B$3)),(OR($E$3="All",'Monthly Activity Log'!B13=$E$3))),'Monthly Activity Log'!B13,"") | C14: =IF(AND(('Monthly Activity Log'!C13<>""),(OR($B$3="All",'Monthly Activity Log'!C13=$B$3)),(OR($E$3="All",'Monthly Activity Log'!B13=$E$3))),'Monthly Activity Log'!C13,"") | D14: =IF(AND(('Monthly Activity Log'!C13<>""),(OR($B$3="All",'Monthly Activity Log'!C13=$B$3)),(OR($E$3="All",'Monthly Activity Log'!B13=$E$3))),'Monthly Activity Log'!D13,"") | E14: =IF(AND(('Monthly Activity Log'!C13<>""),(OR($B$3="All",'Monthly Activity Log'!C13=$B$3)),(OR($E$3="All",'Monthly Activity Log'!B13=$E$3))),'Monthly Activity Log'!E13,"") | F14: =IF(AND(('Monthly Activity Log'!C13<>""),(OR($B$3="All",'Monthly Activity Log'!C13=$B$3)),(OR($E$3="All",'Monthly Activity Log'!B13=$E$3))),'Monthly Activity Log'!F13,"") | G14: =IF(AND(('Monthly Activity Log'!C13<>""),(OR($B$3="All",'Monthly Activity Log'!C13=$B$3)),(OR($E$3="All",'Monthly Activity Log'!B13=$E$3))),'Monthly Activity Log'!G13,"") | H14: =IF(AND(('Monthly Activity Log'!C13<>""),(OR($B$3="All",'Monthly Activity Log'!C13=$B$3)),(OR($E$3="All",'Monthly Activity Log'!B13=$E$3))),'Monthly Activity Log'!H13,"") | I14: =IF(AND(('Monthly Activity Log'!C13<>""),(OR($B$3="All",'Monthly Activity Log'!C13=$B$3)),(OR($E$3="All",'Monthly Activity Log'!B13=$E$3))),'Monthly Activity Log'!I13,"") | J14: =IF(AND(('Monthly Activity Log'!C13<>""),(OR($B$3="All",'Monthly Activity Log'!C13=$B$3)),(OR($E$3="All",'Monthly Activity Log'!B13=$E$3))),'Monthly Activity Log'!J13,"") | K14: =IF(AND(('Monthly Activity Log'!C13<>""),(OR($B$3="All",'Monthly Activity Log'!C13=$B$3)),(OR($E$3="All",'Monthly Activity Log'!B13=$E$3))),'Monthly Activity Log'!K13,"")
A15: =IF(AND(('Monthly Activity Log'!C14<>""),(OR($B$3="All",'Monthly Activity Log'!C14=$B$3)),(OR($E$3="All",'Monthly Activity Log'!B14=$E$3))),ROW()-4,"") | B15: =IF(AND(('Monthly Activity Log'!C14<>""),(OR($B$3="All",'Monthly Activity Log'!C14=$B$3)),(OR($E$3="All",'Monthly Activity Log'!B14=$E$3))),'Monthly Activity Log'!B14,"") | C15: =IF(AND(('Monthly Activity Log'!C14<>""),(OR($B$3="All",'Monthly Activity Log'!C14=$B$3)),(OR($E$3="All",'Monthly Activity Log'!B14=$E$3))),'Monthly Activity Log'!C14,"") | D15: =IF(AND(('Monthly Activity Log'!C14<>""),(OR($B$3="All",'Monthly Activity Log'!C14=$B$3)),(OR($E$3="All",'Monthly Activity Log'!B14=$E$3))),'Monthly Activity Log'!D14,"") | E15: =IF(AND(('Monthly Activity Log'!C14<>""),(OR($B$3="All",'Monthly Activity Log'!C14=$B$3)),(OR($E$3="All",'Monthly Activity Log'!B14=$E$3))),'Monthly Activity Log'!E14,"") | F15: =IF(AND(('Monthly Activity Log'!C14<>""),(OR($B$3="All",'Monthly Activity Log'!C14=$B$3)),(OR($E$3="All",'Monthly Activity Log'!B14=$E$3))),'Monthly Activity Log'!F14,"") | G15: =IF(AND(('Monthly Activity Log'!C14<>""),(OR($B$3="All",'Monthly Activity Log'!C14=$B$3)),(OR($E$3="All",'Monthly Activity Log'!B14=$E$3))),'Monthly Activity Log'!G14,"") | H15: =IF(AND(('Monthly Activity Log'!C14<>""),(OR($B$3="All",'Monthly Activity Log'!C14=$B$3)),(OR($E$3="All",'Monthly Activity Log'!B14=$E$3))),'Monthly Activity Log'!H14,"") | I15: =IF(AND(('Monthly Activity Log'!C14<>""),(OR($B$3="All",'Monthly Activity Log'!C14=$B$3)),(OR($E$3="All",'Monthly Activity Log'!B14=$E$3))),'Monthly Activity Log'!I14,"") | J15: =IF(AND(('Monthly Activity Log'!C14<>""),(OR($B$3="All",'Monthly Activity Log'!C14=$B$3)),(OR($E$3="All",'Monthly Activity Log'!B14=$E$3))),'Monthly Activity Log'!J14,"") | K15: =IF(AND(('Monthly Activity Log'!C14<>""),(OR($B$3="All",'Monthly Activity Log'!C14=$B$3)),(OR($E$3="All",'Monthly Activity Log'!B14=$E$3))),'Monthly Activity Log'!K14,"")
A16: =IF(AND(('Monthly Activity Log'!C15<>""),(OR($B$3="All",'Monthly Activity Log'!C15=$B$3)),(OR($E$3="All",'Monthly Activity Log'!B15=$E$3))),ROW()-4,"") | B16: =IF(AND(('Monthly Activity Log'!C15<>""),(OR($B$3="All",'Monthly Activity Log'!C15=$B$3)),(OR($E$3="All",'Monthly Activity Log'!B15=$E$3))),'Monthly Activity Log'!B15,"") | C16: =IF(AND(('Monthly Activity Log'!C15<>""),(OR($B$3="All",'Monthly Activity Log'!C15=$B$3)),(OR($E$3="All",'Monthly Activity Log'!B15=$E$3))),'Monthly Activity Log'!C15,"") | D16: =IF(AND(('Monthly Activity Log'!C15<>""),(OR($B$3="All",'Monthly Activity Log'!C15=$B$3)),(OR($E$3="All",'Monthly Activity Log'!B15=$E$3))),'Monthly Activity Log'!D15,"") | E16: =IF(AND(('Monthly Activity Log'!C15<>""),(OR($B$3="All",'Monthly Activity Log'!C15=$B$3)),(OR($E$3="All",'Monthly Activity Log'!B15=$E$3))),'Monthly Activity Log'!E15,"") | F16: =IF(AND(('Monthly Activity Log'!C15<>""),(OR($B$3="All",'Monthly Activity Log'!C15=$B$3)),(OR($E$3="All",'Monthly Activity Log'!B15=$E$3))),'Monthly Activity Log'!F15,"") | G16: =IF(AND(('Monthly Activity Log'!C15<>""),(OR($B$3="All",'Monthly Activity Log'!C15=$B$3)),(OR($E$3="All",'Monthly Activity Log'!B15=$E$3))),'Monthly Activity Log'!G15,"") | H16: =IF(AND(('Monthly Activity Log'!C15<>""),(OR($B$3="All",'Monthly Activity Log'!C15=$B$3)),(OR($E$3="All",'Monthly Activity Log'!B15=$E$3))),'Monthly Activity Log'!H15,"") | I16: =IF(AND(('Monthly Activity Log'!C15<>""),(OR($B$3="All",'Monthly Activity Log'!C15=$B$3)),(OR($E$3="All",'Monthly Activity Log'!B15=$E$3))),'Monthly Activity Log'!I15,"") | J16: =IF(AND(('Monthly Activity Log'!C15<>""),(OR($B$3="All",'Monthly Activity Log'!C15=$B$3)),(OR($E$3="All",'Monthly Activity Log'!B15=$E$3))),'Monthly Activity Log'!J15,"") | K16: =IF(AND(('Monthly Activity Log'!C15<>""),(OR($B$3="All",'Monthly Activity Log'!C15=$B$3)),(OR($E$3="All",'Monthly Activity Log'!B15=$E$3))),'Monthly Activity Log'!K15,"")
... A204: =IF(AND(('Monthly Activity Log'!C203<>""),(OR($B$3="All",'Monthly Activity Log'!C203=$B$3)),(OR($E$3="All",'Monthly Activity Log'!B203=$E$3))),ROW()-4,"") | B204: =IF(AND(('Monthly Activity Log'!C203<>""),(OR($B$3="All",'Monthly Activity Log'!C203=$B$3)),(OR($E$3="All",'Monthly Activity Log'!B203=$E$3))),'Monthly Activity Log'!B203,"") | C204: =IF(AND(('Monthly Activity Log'!C203<>""),(OR($B$3="All",'Monthly Activity Log'!C203=$B$3)),(OR($E$3="All",'Monthly Activity Log'!B203=$E$3))),'Monthly Activity Log'!C203,"") | D204: =IF(AND(('Monthly Activity Log'!C203<>""),(OR($B$3="All",'Monthly Activity Log'!C203=$B$3)),(OR($E$3="All",'Monthly Activity Log'!B203=$E$3))),'Monthly Activity Log'!D203,"") | E204: =IF(AND(('Monthly Activity Log'!C203<>""),(OR($B$3="All",'Monthly Activity Log'!C203=$B$3)),(OR($E$3="All",'Monthly Activity Log'!B203=$E$3))),'Monthly Activity Log'!E203,"") | F204: =IF(AND(('Monthly Activity Log'!C203<>""),(OR($B$3="All",'Monthly Activity Log'!C203=$B$3)),(OR($E$3="All",'Monthly Activity Log'!B203=$E$3))),'Monthly Activity Log'!F203,"") | G204: =IF(AND(('Monthly Activity Log'!C203<>""),(OR($B$3="All",'Monthly Activity Log'!C203=$B$3)),(OR($E$3="All",'Monthly Activity Log'!B203=$E$3))),'Monthly Activity Log'!G203,"") | H204: =IF(AND(('Monthly Activity Log'!C203<>""),(OR($B$3="All",'Monthly Activity Log'!C203=$B$3)),(OR($E$3="All",'Monthly Activity Log'!B203=$E$3))),'Monthly Activity Log'!H203,"") | I204: =IF(AND(('Monthly Activity Log'!C203<>""),(OR($B$3="All",'Monthly Activity Log'!C203=$B$3)),(OR($E$3="All",'Monthly Activity Log'!B203=$E$3))),'Monthly Activity Log'!I203,"") | J204: =IF(AND(('Monthly Activity Log'!C203<>""),(OR($B$3="All",'Monthly Activity Log'!C203=$B$3)),(OR($E$3="All",'Monthly Activity Log'!B203=$E$3))),'Monthly Activity Log'!J203,"") | K204: =IF(AND(('Monthly Activity Log'!C203<>""),(OR($B$3="All",'Monthly Activity Log'!C203=$B$3)),(OR($E$3="All",'Monthly Activity Log'!B203=$E$3))),'Monthly Activity Log'!K203,"")

Sheet Client Report
A1: BA Team – Activities by Client
A2: 📌 Updates automatically from Monthly Activity Log. Use the Month filter to narrow results.
A3: Filter: Month | B3: All
A4: Client | B4: Total | C4: Completed | D4: In Progress | E4: Pending | F4: % Completed | G4: % of All Work | H4: Top Assignee | I4: Top Category | J4: Open Items
